<?xml version="1.0" ?>
<!-- =================================================================================== -->
<!-- |    This document was autogenerated by xacro from arm.xacro                      | -->
<!-- |    EDITING THIS FILE BY HAND IS NOT RECOMMENDED                                 | -->
<!-- =================================================================================== -->
<robot name="arm">
  <material name="silver_default">
    <color rgba="0.700 0.700 0.700 1.000"/>
  </material>
  <material name="opaque246246243">
    <color rgba="0.9647058823529412 0.9647058823529412 0.9529411764705882 1.0"/>
  </material>
  <material name="opaque137137137">
    <color rgba="0.5372549019607843 0.5372549019607843 0.5372549019607843 1.0"/>
  </material>
  <material name="opaque245245246">
    <color rgba="0.9607843137254902 0.9607843137254902 0.9647058823529412 1.0"/>
  </material>
  <material name="opaque636363">
    <color rgba="0.24705882352941178 0.24705882352941178 0.24705882352941178 1.0"/>
  </material>
  <transmission name="Revolute 1_tran">
    <type>transmission_interface/SimpleTransmission</type>
    <joint name="Revolute 1">
      <hardwareInterface>hardware_interface/EffortJointInterface</hardwareInterface>
    </joint>
    <actuator name="Revolute 1_actr">
      <hardwareInterface>hardware_interface/EffortJointInterface</hardwareInterface>
      <mechanicalReduction>1</mechanicalReduction>
    </actuator>
  </transmission>
  <transmission name="Revolute 4_tran">
    <type>transmission_interface/SimpleTransmission</type>
    <joint name="Revolute 4">
      <hardwareInterface>hardware_interface/EffortJointInterface</hardwareInterface>
    </joint>
    <actuator name="Revolute 4_actr">
      <hardwareInterface>hardware_interface/EffortJointInterface</hardwareInterface>
      <mechanicalReduction>1</mechanicalReduction>
    </actuator>
  </transmission>
  <transmission name="Revolute 5_tran">
    <type>transmission_interface/SimpleTransmission</type>
    <joint name="Revolute 5">
      <hardwareInterface>hardware_interface/EffortJointInterface</hardwareInterface>
    </joint>
    <actuator name="Revolute 5_actr">
      <hardwareInterface>hardware_interface/EffortJointInterface</hardwareInterface>
      <mechanicalReduction>1</mechanicalReduction>
    </actuator>
  </transmission>
  <transmission name="Revolute 6_tran">
    <type>transmission_interface/SimpleTransmission</type>
    <joint name="Revolute 6">
      <hardwareInterface>hardware_interface/EffortJointInterface</hardwareInterface>
    </joint>
    <actuator name="Revolute 6_actr">
      <hardwareInterface>hardware_interface/EffortJointInterface</hardwareInterface>
      <mechanicalReduction>1</mechanicalReduction>
    </actuator>
  </transmission>
  <transmission name="Revolute 7_tran">
    <type>transmission_interface/SimpleTransmission</type>
    <joint name="Revolute 7">
      <hardwareInterface>hardware_interface/EffortJointInterface</hardwareInterface>
    </joint>
    <actuator name="Revolute 7_actr">
      <hardwareInterface>hardware_interface/EffortJointInterface</hardwareInterface>
      <mechanicalReduction>1</mechanicalReduction>
    </actuator>
  </transmission>
  <transmission name="Revolute 2_tran">
    <type>transmission_interface/SimpleTransmission</type>
    <joint name="Revolute 2">
      <hardwareInterface>hardware_interface/EffortJointInterface</hardwareInterface>
    </joint>
    <actuator name="Revolute 2_actr">
      <hardwareInterface>hardware_interface/EffortJointInterface</hardwareInterface>
      <mechanicalReduction>1</mechanicalReduction>
    </actuator>
  </transmission>
  <transmission name="Revolute 3_tran">
    <type>transmission_interface/SimpleTransmission</type>
    <joint name="Revolute 3">
      <hardwareInterface>hardware_interface/EffortJointInterface</hardwareInterface>
    </joint>
    <actuator name="Revolute 3_actr">
      <hardwareInterface>hardware_interface/EffortJointInterface</hardwareInterface>
      <mechanicalReduction>1</mechanicalReduction>
    </actuator>
  </transmission>
  <link name="base_link">
    <inertial>
      <origin rpy="0 0 0" xyz="-0.009942227184627048 0.020064034929943905 0.025972235101489"/>
      <mass value="2.396454495108003"/>
      <inertia ixx="0.003847" ixy="2.8e-05" ixz="0.000853" iyy="0.004002" iyz="-3e-05" izz="0.002056"/>
    </inertial>
    <visual>
      <origin rpy="0 0 0" xyz="0 0 0"/>
      <geometry>
        <mesh filename="../meshes/base_link.stl" scale="0.001 0.001 0.001"/>
      </geometry>
      <material name="opaque246246243"/>
    </visual>
    <collision>
      <origin rpy="0 0 0" xyz="0 0 0"/>
      <geometry>
        <mesh filename="../meshes/base_link.stl" scale="0.001 0.001 0.001"/>
      </geometry>
    </collision>
  </link>
  <link name="shoulder_link1_1">
    <inertial>
      <origin rpy="0 0 0" xyz="-0.0020200896062955607 0.023458948168524774 -0.06706841096353515"/>
      <mass value="2.2163231597838595"/>
      <inertia ixx="0.00428" ixy="3e-06" ixz="-4e-05" iyy="0.00357" iyz="-0.000152" izz="0.001583"/>
    </inertial>
    <visual>
      <origin rpy="0 0 0" xyz="-0.0 0.0 -0.0"/>
      <geometry>
        <mesh filename="../meshes/shoulder_link1_1.stl" scale="0.001 0.001 0.001"/>
      </geometry>
      <material name="opaque246246243"/>
    </visual>
    <collision>
      <origin rpy="0 0 0" xyz="-0.0 0.0 -0.0"/>
      <geometry>
        <mesh filename="../meshes/shoulder_link1_1.stl" scale="0.001 0.001 0.001"/>
      </geometry>
    </collision>
  </link>
  <link name="elbow_link2_1">
    <inertial>
      <origin rpy="0 0 0" xyz="-0.015464274394364036 0.0002531767802088289 -0.0859377108374576"/>
      <mass value="2.501216447076231"/>
      <inertia ixx="0.005233" ixy="1.4e-05" ixz="-0.000109" iyy="0.006014" iyz="1e-06" izz="0.002048"/>
    </inertial>
    <visual>
      <origin rpy="0 0 0" xyz="-0.019772 -0.020884 0.330118"/>
      <geometry>
        <mesh filename="../meshes/elbow_link2_1_low.stl" scale="0.001 0.001 0.001"/>
      </geometry>
      <material name="opaque137137137"/>
    </visual>
    <collision>
      <origin rpy="0 0 0" xyz="-0.019772 -0.020884 0.330118"/>
      <geometry>
        <mesh filename="../meshes/elbow_link2_1_low.stl" scale="0.001 0.001 0.001"/>
      </geometry>
    </collision>
  </link>
  <link name="wrist_link_1">
    <inertial>
      <origin rpy="0 0 0" xyz="0.0065525949429251565 -7.151574951981196e-05 -0.05054096490230148"/>
      <mass value="1.6086215800000232"/>
      <inertia ixx="0.002472" ixy="2e-06" ixz="0.000402" iyy="0.002637" iyz="-3e-06" izz="0.000726"/>
    </inertial>
    <visual>
      <origin rpy="0 0 0" xyz="-0.0009 -0.021225 0.486339"/>
      <geometry>
        <mesh filename="../meshes/wrist_link_1_low.stl" scale="0.001 0.001 0.001"/>
      </geometry>
      <material name="opaque245245246"/>
    </visual>
    <collision>
      <origin rpy="0 0 0" xyz="-0.0009 -0.021225 0.486339"/>
      <geometry>
        <mesh filename="../meshes/wrist_link_1_low.stl" scale="0.001 0.001 0.001"/>
      </geometry>
    </collision>
  </link>
  <link name="hand1_1">
    <inertial>
      <origin rpy="0 0 0" xyz="-0.034498767587359806 0.020017116621166668 -0.05964944263936478"/>
      <mass value="1.5629058767642119"/>
      <inertia ixx="0.00275" ixy="-6e-06" ixz="-0.00066" iyy="0.002992" iyz="-1.2e-05" izz="0.000866"/>
    </inertial>
    <visual>
      <origin rpy="0 0 0" xyz="-0.037254 -0.002265 0.592574"/>
      <geometry>
        <mesh filename="../meshes/hand1_1.stl" scale="0.001 0.001 0.001"/>
      </geometry>
      <material name="opaque636363"/>
    </visual>
    <collision>
      <origin rpy="0 0 0" xyz="-0.037254 -0.002265 0.592574"/>
      <geometry>
        <mesh filename="../meshes/hand1_1.stl" scale="0.001 0.001 0.001"/>
      </geometry>
    </collision>
  </link>
  <link name="hand2_1">
    <inertial>
      <origin rpy="0 0 0" xyz="-0.01040695508919266 0.019307989916875906 -0.04879276359391038"/>
      <mass value="0.6693428444848912"/>
      <inertia ixx="0.000698" ixy="-3e-06" ixz="-5.2e-05" iyy="0.000597" iyz="-7e-06" izz="0.000165"/>
    </inertial>
    <visual>
      <origin rpy="0 0 0" xyz="-0.024755 -0.002991 0.641193"/>
      <geometry>
        <mesh filename="../meshes/hand2_1.stl" scale="0.001 0.001 0.001"/>
      </geometry>
      <material name="opaque245245246"/>
    </visual>
    <collision>
      <origin rpy="0 0 0" xyz="-0.024755 -0.002991 0.641193"/>
      <geometry>
        <mesh filename="../meshes/hand2_1.stl" scale="0.001 0.001 0.001"/>
      </geometry>
    </collision>
  </link>
  <link name="shoulder_link2_1">
    <inertial>
      <origin rpy="0 0 0" xyz="0.025085901149047445 -0.0004898024402024553 -0.05090240468378998"/>
      <mass value="1.7846079164526971"/>
      <inertia ixx="0.002118" ixy="6e-06" ixz="-7.7e-05" iyy="0.002476" iyz="1e-06" izz="0.001313"/>
    </inertial>
    <visual>
      <origin rpy="0 0 0" xyz="0.021747 -0.021634 0.091118"/>
      <geometry>
        <mesh filename="../meshes/shoulder_link2_1.stl" scale="0.001 0.001 0.001"/>
      </geometry>
      <material name="opaque137137137"/>
    </visual>
    <collision>
      <origin rpy="0 0 0" xyz="0.021747 -0.021634 0.091118"/>
      <geometry>
        <mesh filename="../meshes/shoulder_link2_1.stl" scale="0.001 0.001 0.001"/>
      </geometry>
    </collision>
  </link>
  <link name="elbow_link1_1">
    <inertial>
      <origin rpy="0 0 0" xyz="-2.8668518769238874e-05 -2.5267618562929e-05 -0.10371499274239299"/>
      <mass value="2.526187654854094"/>
      <inertia ixx="0.00722" ixy="0.0" ixz="2.7e-05" iyy="0.007178" iyz="-4e-06" izz="0.001143"/>
    </inertial>
    <visual>
      <origin rpy="0 0 0" xyz="0.0 -0.021241 0.174618"/>
      <geometry>
        <mesh filename="../meshes/elbow_link1_1_low.stl" scale="0.001 0.001 0.001"/>
      </geometry>
      <material name="opaque137137137"/>
    </visual>
    <collision>
      <origin rpy="0 0 0" xyz="0.0 -0.021241 0.174618"/>
      <geometry>
        <mesh filename="../meshes/elbow_link1_1_low.stl" scale="0.001 0.001 0.001"/>
      </geometry>
    </collision>
  </link>
  <joint name="Revolute 1" type="revolute">
    <origin rpy="0 0 0" xyz="0.0 0.0 0.0"/>
    <parent link="base_link"/>
    <child link="shoulder_link1_1"/>
    <axis xyz="0.0 1.0 0.0"/>
    <limit effort="100" lower="-1.745329" upper="1.570796" velocity="100"/>
  </joint>
  <joint name="Revolute 4" type="revolute">
    <origin rpy="0 0 0" xyz="0.019772 -0.000357 -0.1555"/>
    <parent link="elbow_link1_1"/>
    <child link="elbow_link2_1"/>
    <axis xyz="0.999837 -0.018051 0.0"/>
    <limit effort="100" lower="-1.570796" upper="1.570796" velocity="100"/>
  </joint>
  <joint name="Revolute 5" type="revolute">
    <origin rpy="0 0 0" xyz="-0.018872 0.000341 -0.156221"/>
    <parent link="elbow_link2_1"/>
    <child link="wrist_link_1"/>
    <axis xyz="0.0 0.0 -1.0"/>
    <limit effort="100" lower="-3.141593" upper="3.141593" velocity="100"/>
  </joint>
  <joint name="Revolute 6" type="revolute">
    <origin rpy="0 0 0" xyz="0.036354 -0.01896 -0.106235"/>
    <parent link="wrist_link_1"/>
    <child link="hand1_1"/>
    <axis xyz="-0.018051 -0.999837 -0.0"/>
    <limit effort="100" lower="0.0" upper="2.617994" velocity="100"/>
  </joint>
  <joint name="Revolute 7" type="revolute">
    <origin rpy="0 0 0" xyz="-0.012499 0.000726 -0.048619"/>
    <parent link="hand1_1"/>
    <child link="hand2_1"/>
    <axis xyz="-0.018051 -0.999837 -0.0"/>
    <limit effort="100" lower="0.0" upper="1.047198" velocity="100"/>
  </joint>
  <joint name="Revolute 2" type="revolute">
    <origin rpy="0 0 0" xyz="-0.021747 0.021634 -0.091118"/>
    <parent link="shoulder_link1_1"/>
    <child link="shoulder_link2_1"/>
    <axis xyz="-0.999837 0.018051 -0.0"/>
    <limit effort="100" lower="-1.570796" upper="1.570796" velocity="100"/>
  </joint>
  <joint name="Revolute 3" type="revolute">
    <origin rpy="0 0 0" xyz="0.021747 -0.000393 -0.0835"/>
    <parent link="shoulder_link2_1"/>
    <child link="elbow_link1_1"/>
    <axis xyz="-0.0 -0.0 -1.0"/>
    <limit effort="100" lower="-3.141593" upper="3.141593" velocity="100"/>
  </joint>
</robot>
